Workbook

Sheet TOTAL
A1: JURISDICCIÓN | B1: 43466 | C1: 43497 | D1: 43525 | E1: 43556 | F1: 43586 | G1: 43617 | H1: 43647 | I1: 43678 | J1: 43709 | K1: 43739 | L1: 43770 | M1: 43800 | N1: 43831 | O1: 43862 | P1: 43891 | Q1: 43922 | R1: 43952 | S1: 43983 | T1: 44013 | U1: 44044 | V1: 44075 | W1: 44105 | X1: 44136 | Y1: 44166 | Z1: 44197 | AA1: 44228 | AB1: 44256 | AC1: 44287 | AD1: 44317 | AE1: 44348 | AF1: 44378 | AG1: 44409 | AH1: 44440 | AI1: 44470 | AJ1: 44501 | AK1: 44531 | AL1: 44562 | AM1: 44593 | AN1: 44621 | AO1: 44652 | AP1: 44682 | AQ1: 44713 | AR1: 44743 | AS1: 44774 | AT1: 44805 | AU1: 44835 | AV1: 44866 | AW1: 44896 | AX1: 44927 | AY1: 44958 | AZ1: 44986 | BA1: 45017 | BB1: 45047 | BC1: 45078 | BD1: 45108 | BE1: 45139 | BF1: 45170 | BG1: 45200 | BH1: 45231 | BI1: 45261 | BJ1: 45292 | BK1: 45323 | BL1: 45352 | BM1: 45383 | BN1: 45413 | BO1: 45444 | BP1: 45474 | BQ1: 45505 | BR1: 45536 | BS1: 45566 | BT1: 45597 | BU1: 45627 | BV1: 45658 | BW1: 45689 | BX1: 45717 | BY1: 45748 | BZ1: 45778 | CA1: 45809 | CB1: 45839 | CC1: 45870 | CD1: 45901 | CE1: 45931 | CF1: 45962 | CG1: 45992 | CH1: 46023 | CI1: 46054 | CJ1: 46082 | CK1: 46113 | CL1: 46143 | CM1: 46174 | CN1: 46204 | CO1: 46235
A2: Buenos Aires | B2: 29680.858 | C2: 28537.857 | D2: 27501.723 | E2: 26581.721 | F2: 28541.036 | G2: 30179.504 | H2: 29913.642 | I2: 30779.904 | J2: 35286.023 | K2: 32454.938 | L2: 35450.324 | M2: 31097.862 | N2: 34848.602 | O2: 35932.181 | P2: 42339.593 | Q2: 29626.194 | R2: 32464.636 | S2: 36599.182 | T2: 37355.418 | U2: 38826.931 | V2: 43598.884 | W2: 41198.27 | X2: 48105.493 | Y2: 46121.443 | Z2: 56690.132 | AA2: 57983.467 | AB2: 62049.556 | AC2: 60648.794 | AD2: 61924.734 | AE2: 68709.167 | AF2: 68552.46 | AG2: 63003.763 | AH2: 70728.293 | AI2: 70356.599 | AJ2: 77179.567 | AK2: 73652.277 | AL2: 75776.7 | AM2: 86120.189 | AN2: 105365.04 | AO2: 98127.153 | AP2: 108686.84 | AQ2: 118643.06 | AR2: 128373.53 | AS2: 124566.75 | AT2: 140706.02 | AU2: 138737.7 | AV2: 146941.32 | AW2: 136722.59 | AX2: 154759.04 | AY2: 165427.35 | AZ2: 200136.55 | BA2: 194928.38 | BB2: 210181.96 | BC2: 235321.52 | BD2: 252518.85 | BE2: 265664.18 | BF2: 307375.37 | BG2: 326323.04 | BH2: 366637.04 | BI2: 361136.78 | BJ2: 480894.47 | BK2: 617285.33 | BL2: 840195.61 | BM2: 726206.38 | BN2: 692067.64 | BO2: 782001.43 | BP2: 804133.83 | BQ2: 858082.37 | BR2: 919350.82 | BS2: 971268.52 | BT2: 1043542.8 | BU2: 914225.48 | BV2: 950706.14 | BW2: 921021.1 | BX2: 1083447.6 | BY2: 1104931.3 | BZ2: 1162835.8 | CA2: 1145940.5 | CB2: 1215758.3 | CC2: 1208999.6 | CD2: 1295553.4 | CE2: 1221182.1 | CF2: 1316795.8 | CG2: 1320151 | CH2: 1314352.3 | CI2: 1319640.4 | CJ2: 1366397.4 | CK2: 1425233.9 | CL2: 1341638.8 | CM2: 1562091.8 | CN2: 1488013.8
A3: CABA | B3: 19003.5 | C3: 17988.5 | D3: 14975.3 | E3: 17967.7 | F3: 17590.6 | G3: 18633.6 | H3: 18470.2 | I3: 20479.2 | J3: 20945.2 | K3: 21578 | L3: 23029.3 | M3: 23020.6 | N3: 27701.7 | O3: 25799.4 | P3: 20488.7 | Q3: 19240.4 | R3: 19960.1 | S3: 22778 | T3: 23452 | U3: 26778.5 | V3: 27814.4 | W3: 30321 | X3: 28871.9 | Y3: 31272.6 | Z3: 38638.9 | AA3: 38863.2 | AB3: 34049.3 | AC3: 40842.1 | AD3: 40668.4 | AE3: 43917.7 | AF3: 43967.1 | AG3: 48845.5 | AH3: 48735.2 | AI3: 51702.4 | AJ3: 52987.6 | AK3: 58870.9 | AL3: 63094.2 | AM3: 62066.4 | AN3: 55506.3 | AO3: 68823.5 | AP3: 69142.3 | AQ3: 78343.8 | AR3: 81670.7 | AS3: 91834.5 | AT3: 96997.8 | AU3: 108956.6 | AV3: 113051.8 | AW3: 126672.4 | AX3: 142995.5 | AY3: 142053.6 | AZ3: 130190.6 | BA3: 158522.4 | BB3: 164075.7 | BC3: 193255.5 | BD3: 207775.7 | BE3: 229161.7 | BF3: 266894.7 | BG3: 301105.3 | BH3: 324781.7 | BI3: 360778.2 | BJ3: 466525.1 | BK3: 474364.8 | BL3: 458538.3 | BM3: 527925.7 | BN3: 542932.8 | BO3: 582367.6 | BP3: 551658.9 | BQ3: 631043.4 | BR3: 635860.2 | BS3: 638998.8 | BT3: 659182.5 | BU3: 687956.5 | BV3: 729043.3 | BW3: 768506.5 | BX3: 670256.3 | BY3: 789995.5 | BZ3: 794195 | CA3: 790697.5 | CB3: 785857.2 | CC3: 891886.5 | CD3: 886387.7 | CE3: 962840.6 | CF3: 939760.5 | CG3: 934708.3 | CH3: 1124942.9 | CI3: 973721.7 | CJ3: 834884.7 | CK3: 953683.4 | CL3: 944690.1 | CM3: 973905.3 | CN3: 980445.6 | CO3: 1050165.9
A4: Catamarca | B4: 351.2957 | C4: 327.76971 | D4: 370.93105 | E4: 343.39 | F4: 348.02061 | G4: 344.32519 | H4: 352.03075 | I4: 355.6633 | J4: 392.85482 | K4: 428.79091 | L4: 440.2345 | M4: 400.28964 | N4: 420.39319 | O4: 434.28226 | P4: 425.20392 | Q4: 446.2158 | R4: 433.91593 | S4: 493.06383 | T4: 519.11997 | U4: 521.64472 | V4: 514.2556 | W4: 525.38448 | X4: 530.45199 | Y4: 552.75429 | Z4: 623.21519 | AA4: 631.97928 | AB4: 861.825 | AC4: 893.447 | AD4: 801.82084 | AE4: 811.64348 | AF4: 863.44634 | AG4: 907.32067 | AH4: 1041.3081 | AI4: 1111.2664 | AJ4: 1222.5505 | AK4: 1327.3173 | AL4: 1229.006 | AM4: 1205.6261 | AN4: 1535.7669 | AO4: 1303.3324 | AP4: 1384.8493 | AQ4: 2108.2636 | AR4: 1745.9278 | AS4: 2177.7441 | AT4: 2262.9317 | AU4: 2194.9974 | AV4: 2494.2676 | AW4: 2489.5071 | AX4: 2652.4489 | AY4: 2433.636 | AZ4: 3045.7955 | BA4: 3393.9107 | BB4: 3496.6058 | BC4: 4019.8485 | BD4: 4766.5711 | BE4: 5040.5635 | BF4: 5261.2499 | BG4: 5776.3006 | BH4: 6736.9597 | BI4: 6437.4898 | BJ4: 9011.035 | BK4: 10267.634 | BL4: 10863.912 | BM4: 11811.182 | BN4: 13426.905 | BO4: 13425.774 | BP4: 13214.964 | BQ4: 14299.038 | BR4: 15255.18 | BS4: 16171.937 | BT4: 17650.753 | BU4: 16453.721 | BV4: 18336.239 | BW4: 16432.214 | BX4: 16871.126 | BY4: 18024.179 | BZ4: 19390.64 | CA4: 18696.302 | CB4: 19169.053 | CC4: 18736.379 | CD4: 19756.723 | CE4: 21018.336 | CF4: 19752.246 | CG4: 19101.915 | CH4: 23332.946 | CI4: 20973.172 | CJ4: 22667.205 | CK4: 24745.498 | CL4: 23439.128 | CM4: 23912.582 | CN4: 26317.415 | CO4: 23795.668
A5: Chaco | B5: 943.19063 | C5: 818.72453 | D5: 782.58334 | E5: 818.9958 | F5: 857.96345 | G5: 863.77643 | H5: 957.18627 | I5: 996.65939 | J5: 1123.2953 | K5: 1029.489 | L5: 1124.0601 | M5: 1100.6442 | N5: 1485.2558 | O5: 1276.2675 | P5: 1118.5462 | Q5: 1069.9301 | R5: 1163.6956 | S5: 1350.1275 | T5: 1391.051 | U5: 1513.0975 | V5: 1461.0965 | W5: 1539.3247 | X5: 1662.7819 | Y5: 1670.8209 | Z5: 1925.7438 | AA5: 1789.9781 | AB5: 1882.1981 | AC5: 2078.5863 | AD5: 2150.7314 | AE5: 2283.7712 | AF5: 2605.7492 | AG5: 2691.6792 | AH5: 2681.1452 | AI5: 2805.7675 | AJ5: 2920.6716 | AK5: 3085.2588 | AL5: 3237.8941 | AM5: 2991.5296 | AN5: 3189.0974 | AO5: 3529.3747 | AP5: 4049.7521 | AQ5: 4338.3328 | AR5: 4807.0841 | AS5: 4847.1947 | AT5: 5109.042 | AU5: 5587.2009 | AV5: 5722.5897 | AW5: 6064.6241 | AX5: 6802.7267 | AY5: 6086.9462 | AZ5: 6865.2451 | BA5: 7228.3 | BB5: 8379.0532 | BC5: 9075.2492 | BD5: 10044.571 | BE5: 10796.275 | BF5: 11724.879 | BG5: 13048.568 | BH5: 13522.498 | BI5: 14608.816 | BJ5: 17662.119 | BK5: 18712.617 | BL5: 20464.553 | BM5: 21457.625 | BN5: 23370.478 | BO5: 26239.646 | BP5: 29697.472 | BQ5: 31673.721 | BR5: 32970.863 | BS5: 32378.983 | BT5: 33978.016 | BU5: 34515.384 | BV5: 38571.273 | BW5: 35800.391 | BX5: 33753.801 | BY5: 35555.397 | BZ5: 38779.88 | CA5: 38588.46 | CB5: 41110.003 | CC5: 42942.838 | CD5: 41390.69 | CE5: 42603.927 | CF5: 42263.135 | CG5: 45503.304 | CH5: 53382.838 | CI5: 47320.405 | CJ5: 43880.078 | CK5: 45869.569 | CL5: 46798.855 | CM5: 50190.389 | CN5: 56675.629 | CO5: 55139.167
A6: Chubut (*) | B6: 1222 | C6: 1085 | D6: 1124 | E6: 1197 | F6: 1280 | G6: 1168 | H6: 1252 | I6: 1374 | J6: 1357 | K6: 1528 | L6: 1551 | M6: 1402 | N6: 1571 | O6: 1629 | P6: 1456 | Q6: 1233 | R6: 1184 | S6: 1281 | T6: 1232 | U6: 1258 | V6: 1629 | W6: 1809 | X6: 1837 | Y6: 1841 | Z6: 2198 | AA6: 2051 | AB6: 2238 | AC6: 2440 | AD6: 2584 | AE6: 2666 | AF6: 2836 | AG6: 2892 | AH6: 3045 | AI6: 2914 | AJ6: 3058 | AK6: 3263 | AL6: 3566 | AM6: 3135 | AN6: 3362 | AO6: 3780 | AP6: 3750 | AQ6: 4012 | AR6: 4956 | AS6: 5054 | AT6: 5519 | AU6: 5535 | AV6: 5974 | AW6: 6719 | AX6: 7897 | AY6: 7214 | AZ6: 7706 | BA6: 8881 | BB6: 9289 | BC6: 8982 | BD6: 10751 | BE6: 12540 | BF6: 13022 | BG6: 15184 | BH6: 14835 | BI6: 16742 | BJ6: 24429 | BK6: 28165 | BL6: 27403 | BM6: 29604 | BN6: 31552 | BO6: 36380 | BP6: 34156 | BQ6: 36408 | BR6: 36669 | BS6: 38223 | BT6: 40722 | BU6: 42342 | BV6: 48609 | BW6: 44540 | BX6: 43308 | BY6: 44639 | BZ6: 46392 | CA6: 47642 | CB6: 51893 | CC6: 53369 | CD6: 52717 | CE6: 57672 | CF6: 51628 | CG6: 58194 | CH6: 74710 | CI6: 57269 | CJ6: 61598 | CK6: 60290 | CL6: 59655 | CM6: 60048 | CN6: 70301 | CO6: 65116
A7: Córdoba | B7: 6585.9407 | C7: 7664.4591 | D7: 7094.6232 | E7: 6748.7779 | F7: 7553.7562 | G7: 6635.7543 | H7: 7149.6188 | I7: 7865.0804 | J7: 8016.4446 | K7: 8129.8389 | L7: 8268.1295 | M7: 8253.8274 | N7: 9876.9331 | O7: 11322.622 | P7: 8859.1569 | Q7: 8084.6302 | R7: 8847.988 | S7: 8979.0266 | T7: 9488.1881 | U7: 10227.535 | V7: 10582.196 | W7: 10667.068 | X7: 11104.672 | Y7: 11686.009 | Z7: 13846.633 | AA7: 15614.328 | AB7: 14801.589 | AC7: 15217.281 | AD7: 18041.554 | AE7: 15141.908 | AF7: 15974.797 | AG7: 17612.127 | AH7: 17832.914 | AI7: 17677.322 | AJ7: 19022.433 | AK7: 20047.551 | AL7: 22140.842 | AM7: 23798.769 | AN7: 22781.034 | AO7: 24113.036 | AP7: 30462.202 | AQ7: 26544.985 | AR7: 29032.784 | AS7: 30275.892 | AT7: 32125.77 | AU7: 32522.375 | AV7: 34068.874 | AW7: 35045.644 | AX7: 40879.493 | AY7: 41500.307 | AZ7: 44257.502 | BA7: 45597.55 | BB7: 59047.401 | BC7: 53704.885 | BD7: 57695.852 | BE7: 65144.968 | BF7: 70728.438 | BG7: 81074.467 | BH7: 87434.108 | BI7: 94216.66 | BJ7: 131734.59 | BK7: 175734.52 | BL7: 165774.69 | BM7: 169084.83 | BN7: 177016.29 | BO7: 182312.1 | BP7: 181787.92 | BQ7: 207233.27 | BR7: 210689.99 | BS7: 212882.65 | BT7: 219549.52 | BU7: 218358.02 | BV7: 250196.69 | BW7: 327689.1 | BX7: 278105.96 | BY7: 272980.68 | BZ7: 312489.53 | CA7: 291838.36 | CB7: 305415.29 | CC7: 323243.17 | CD7: 302231.79 | CE7: 316399.69 | CF7: 300963.03 | CG7: 352803.02 | CH7: 379862.65 | CI7: 382541.59 | CJ7: 374801.15 | CK7: 378991.5 | CL7: 414439.31 | CM7: 368427.54 | CN7: 359489.66 | CO7: 363399.77
A8: Corrientes | B8: s.d | C8: s.d | D8: s.d | E8: s.d | F8: s.d | G8: s.d | H8: s.d | I8: s.d | J8: s.d | K8: s.d | L8: s.d | M8: s.d | N8: s.d | O8: s.d | P8: s.d | Q8: s.d | R8: s.d | S8: s.d | T8: s.d | U8: s.d | V8: s.d | W8: s.d | X8: s.d | Y8: s.d | Z8: s.d | AA8: s.d | AB8: s.d | AC8: s.d | AD8: s.d | AE8: s.d | AF8: s.d | AG8: s.d | AH8: s.d | AI8: s.d | AJ8: s.d | AK8: s.d | AL8: s.d | AM8: s.d | AN8: s.d | AO8: s.d | AP8: s.d | AQ8: s.d | AR8: s.d | AS8: s.d | AT8: s.d | AU8: s.d | AV8: s.d | AW8: s.d | AX8: s.d | AY8: s.d | AZ8: s.d | BA8: s.d | BB8: s.d | BC8: s.d | BD8: s.d | BE8: s.d | BF8: s.d | BG8: s.d | BH8: s.d | BI8: s.d | BJ8: 14072.429 | BK8: 15169.561 | BL8: 15588.337 | BM8: 18501.482 | BN8: 19399.699 | BO8: 20058.657 | BP8: 20858.851 | BQ8: 25006.505 | BR8: 24621.062 | BS8: 24934.117 | BT8: 26185.131 | BU8: 26301.25 | BV8: 28734.35 | BW8: 28538.73 | BX8: 27917.88 | BY8: 32056.739 | BZ8: 30922.658 | CA8: 31354.435 | CB8: 31063.301 | CC8: 34884.768 | CD8: 33979.573 | CE8: 33639.37 | CF8: 32248.958 | CG8: 33021.938 | CH8: 36675.858 | CI8: 34887.552 | CJ8: 34282.887 | CK8: 42881.275 | CL8: 37981.387 | CM8: 40071.712 | CN8: 39408.301
A9: Entre Ríos | B9: 1680.9501 | C9: 1941.4 | D9: 2111.4665 | E9: 2617.1183 | F9: 2167.2347 | G9: 2167.6922 | H9: 2216.7487 | I9: 2094.3213 | J9: 2302.6836 | K9: 2639.4532 | L9: 2373.2331 | M9: 2648.7049 | N9: 2246.9604 | O9: 2949.8367 | P9: 2653.1327 | Q9: 1776.2469 | R9: 2934.1221 | S9: 2920.2885 | T9: 3042.3672 | U9: 2996.4383 | V9: 3113.9528 | W9: 3548.9809 | X9: 3334.6137 | Y9: 3720.55 | Z9: 3249.9962 | AA9: 4285.625 | AB9: 4509.8594 | AC9: 4917.94 | AD9: 4336.2042 | AE9: 4872.0617 | AF9: 5210.3001 | AG9: 5322.2983 | AH9: 5594.576 | AI9: 6138.5916 | AJ9: 5841.1216 | AK9: 6447.5619 | AL9: 5561.6081 | AM9: 6477.5281 | AN9: 7234.9761 | AO9: 5949.2095 | AP9: 8561.0631 | AQ9: 7740.7778 | AR9: 8313.6694 | AS9: 8517.8939 | AT9: 9285.1764 | AU9: 10181.953 | AV9: 9756.207 | AW9: 11026.197 | AX9: 10372.882 | AY9: 11700.825 | AZ9: 13869.089 | BA9: 11799.974 | BB9: 16205.684 | BC9: 15554.159 | BD9: 16586.754 | BE9: 18799.919 | BF9: 21294.818 | BG9: 23421.449 | BH9: 25176.721 | BI9: 27684.134 | BJ9: 32376.141 | BK9: 33136.792 | BL9: 36260.871 | BM9: 47202.371 | BN9: 61325.902 | BO9: 50751.624 | BP9: 60662.572 | BQ9: 56630.649 | BR9: 60155.662 | BS9: 59172.592 | BT9: 61164.082 | BU9: 62273.921 | BV9: 60611.284 | BW9: 56926.821 | BX9: 73431.183 | BY9: 75444.238 | BZ9: 94545.994 | CA9: 77348.22 | CB9: 90239.405 | CC9: 83455.127 | CD9: 92340.689 | CE9: 98257.182 | CF9: 88651.525 | CG9: 97364.229 | CH9: 87247.695 | CI9: 97862.767 | CJ9: 85205.289 | CK9: 120566.05 | CL9: 125713.91 | CM9: 100416.75 | CN9: 118601.24 | CO9: 104652.42
A10: Formosa | B10: 265.12981 | C10: 289.66041 | D10: 280.26161 | E10: 293.85058 | F10: 310.13555 | G10: 315.60277 | H10: 307.62959 | I10: 345.44647 | J10: 350.7291 | K10: 338.05382 | L10: 366.10381 | M10: 366.11215 | N10: 367.19862 | O10: 382.36475 | P10: 360.59382 | Q10: 312.33454 | R10: 314.07284 | S10: 371.68994 | T10: 402.6653 | U10: 441.64964 | V10: 456.53456 | W10: 488.30648 | X10: 524.19867 | Y10: 547.65932 | Z10: 588.86293 | AA10: 581.38934 | AB10: 705.41543 | AC10: 746.75 | AD10: 738.98284 | AE10: 722.70508 | AF10: 779.04661 | AG10: 906.35619 | AH10: 975.10468 | AI10: 976.36244 | AJ10: 1077.4853 | AK10: 1055.1583 | AL10: 1192.5463 | AM10: 1074.5273 | AN10: 1177.5424 | AO10: 1358.6219 | AP10: 1417.772 | AQ10: 1474.5474 | AR10: 1715.8009 | AS10: 1775.9435 | AT10: 1999.5665 | AU10: 1936.2196 | AV10: 2040.916 | AW10: 2266.2684 | AX10: 2355.1659 | AY10: 2288.6544 | AZ10: 2583.4852 | BA10: 2773.5361 | BB10: 2971.1808 | BC10: 3215.3233 | BD10: 3632.4131 | BE10: 4076.2093 | BF10: 4345.6831 | BG10: 4449.8718 | BH10: 4806.7261 | BI10: 5257.1045 | BJ10: 5779.3639 | BK10: 5536.7562 | BL10: 6893.4582 | BM10: 6796.8086 | BN10: 7773.0872 | BO10: 9150.8299 | BP10: 8812.8325 | BQ10: 11039.93 | BR10: 10508.739 | BS10: 10550.935 | BT10: 11299.271 | BU10: 11901.648 | BV10: 11602.109 | BW10: 12973.399 | BX10: 12691.8 | BY10: 13214.463 | BZ10: 13786.964 | CA10: 13852.899 | CB10: 14213.32 | CC10: 15435.059 | CD10: 14849.635 | CE10: 15396.371 | CF10: 14386.098 | CG10: 15015.557 | CH10: 15622.652 | CI10: 15311.048 | CJ10: 15059.392 | CK10: 16479.303 | CL10: 19054.415 | CM10: 18901.155 | CN10: 19011.315 | CO10: 20484.743
A11: Jujuy | B11: 547.199 | C11: 588.032 | D11: 516.964 | E11: 477.593 | F11: 509 | G11: 502.958 | H11: 500.857 | I11: 558.3 | J11: 595.404 | K11: 639.307 | L11: 597.543 | M11: 631.906 | N11: 685.064 | O11: 792.138 | P11: 603.247 | Q11: 444.43 | R11: 567.638 | S11: 566.459 | T11: 584.344 | U11: 625.467 | V11: 617.479 | W11: 748.812 | X11: 752.858 | Y11: 830.23824 | Z11: 1054.806 | AA11: 1133.634 | AB11: 1211.4612 | AC11: 1196.1296 | AD11: 1158.177 | AE11: 1313.8381 | AF11: 1343.6981 | AG11: 1426.6937 | AH11: 1481.9906 | AI11: 1512.4325 | AJ11: 1599.4275 | AK11: 1714.9384 | AL11: 1940.9647 | AM11: 1981.6039 | AN11: 1946.0316 | AO11: 2025.4289 | AP11: 2188.0386 | AQ11: 2214.2971 | AR11: 2677.0736 | AS11: 2844.938 | AT11: 2826.4303 | AU11: 3028.5259 | AV11: 3221.5358 | AW11: 3413.1883 | AX11: 4342.8114 | AY11: 4231.9188 | AZ11: 4638.1725 | BA11: 4749.5222 | BB11: 4914.75 | BC11: 5013.9706 | BD11: 5930.2528 | BE11: 6333.8061 | BF11: 7280.763 | BG11: 8053.3988 | BH11: 8486.3787 | BI11: 9559.4508 | BJ11: 13847.018 | BK11: 13415.881 | BL11: 13785.8 | BM11: 14587.581 | BN11: 14808.386 | BO11: 15539.573 | BP11: 17166.977 | BQ11: 17819.381 | BR11: 19578.117 | BS11: 19739.948 | BT11: 20863.954 | BU11: 21305.762 | BV11: 23788.554 | BW11: 24996.322 | BX11: 22963.229 | BY11: 23465.508 | BZ11: 24755.611 | CA11: 24521.851 | CB11: 26412.351 | CC11: 29943.939 | CD11: 27026.134 | CE11: 29913.57 | CF11: 28170.328 | CG11: 29767.191 | CH11: 32644.881 | CI11: 32655.193 | CJ11: 34438.588 | CK11: 34964.22 | CL11: 33839.98 | CM11: 34647.516 | CN11: 37388.89 | CO11: 38939.414
A12: La Pampa | B12: s.d | C12: s.d | D12: s.d | E12: s.d | F12: s.d | G12: s.d | H12: s.d | I12: s.d | J12: s.d | K12: s.d | L12: s.d | M12: s.d | N12: s.d | O12: s.d | P12: s.d | Q12: s.d | R12: s.d | S12: s.d | T12: s.d | U12: s.d | V12: s.d | W12: s.d | X12: s.d | Y12: s.d | Z12: s.d | AA12: s.d | AB12: s.d | AC12: s.d | AD12: s.d | AE12: s.d | AF12: s.d | AG12: s.d | AH12: s.d | AI12: s.d | AJ12: s.d | AK12: s.d | AL12: s.d | AM12: s.d | AN12: s.d | AO12: s.d | AP12: s.d | AQ12: s.d | AR12: s.d | AS12: s.d | AT12: s.d | AU12: s.d | AV12: s.d | AW12: s.d | AX12: s.d | AY12: s.d | AZ12: s.d | BA12: s.d | BB12: s.d | BC12: s.d | BD12: s.d | BE12: s.d | BF12: s.d | BG12: s.d | BH12: s.d | BI12: s.d | BJ12: 17276.514 | BK12: 18036.229 | BL12: 17227.129 | BM12: 21474.241 | BN12: 20830.442 | BO12: 22999.327 | BP12: 25596.088 | BQ12: 26079.003 | BR12: 26582.928 | BS12: 27342.312 | BT12: 27041.647 | BU12: 36962.117 | BV12: 30619.836 | BW12: 29182.77 | BX12: 26938.104 | BY12: 33237.304 | BZ12: 32327.648 | CA12: 37856.425 | CB12: 37527.368 | CC12: 40021.025 | CD12: 41342.063 | CE12: 40010.083 | CF12: 35329.226 | CG12: 46704.531 | CH12: 42621.86 | CI12: 31483.763 | CJ12: 43979.383 | CK12: 45879.785 | CL12: 43696.355 | CM12: 54782.982 | CN12: 51983.235
A13: La Rioja | B13: 220.49854 | C13: 202.4897 | D13: 254.44622 | E13: 234.5311 | F13: 212.3326 | G13: 218.98995 | H13: 230.45788 | I13: 270.04676 | J13: 295.33083 | K13: 258.45885 | L13: 285.02929 | M13: 274.54019 | N13: 303.97125 | O13: 268.8511 | P13: 301.29659 | Q13: 228.64098 | R13: 251.0557 | S13: 259.95329 | T13: 293.88728 | U13: 287.85867 | V13: 293.2186 | W13: 334.53231 | X13: 364.55918 | Y13: 390.61597 | Z13: 497.21247 | AA13: 491.97551 | AB13: 620.74091 | AC13: 625.09 | AD13: 520.07515 | AE13: 574.51548 | AF13: 588.83318 | AG13: 623.51575 | AH13: 665.55702 | AI13: 676.92737 | AJ13: 729.87197 | AK13: 826.46441 | AL13: 850.13047 | AM13: 735.81119 | AN13: 1026.717 | AO13: 937.41675 | AP13: 956.37365 | AQ13: 1041.7753 | AR13: 1144.2198 | AS13: 1248.0487 | AT13: 1353.087 | AU13: 1402.346 | AV13: 1555.3686 | AW13: 1710.8127 | AX13: 1596.089 | AY13: 1454.7067 | AZ13: 2122.6989 | BA13: 2068.3747 | BB13: 2217.354 | BC13: 2335.418 | BD13: 2631.7946 | BE13: 2887.6074 | BF13: 3138.7155 | BG13: 3301.021 | BH13: 3672.532 | BI13: 4090.8856 | BJ13: 4903.4843 | BK13: 5498.7073 | BL13: 5739.3065 | BM13: 7403.6915 | BN13: 7045.9435 | BO13: 7530.1238 | BP13: 9093.565 | BQ13: 9792.3247 | BR13: 9682.7452 | BS13: 11158.491 | BT13: 12451.678 | BU13: 11104.731 | BV13: 13522.496 | BW13: 10991.777 | BX13: 12293.221 | BY13: 13050.151 | BZ13: 12269.84 | CA13: 12730.91 | CB13: 13484.955 | CC13: 14285.074 | CD13: 14454.318 | CE13: 13519.559 | CF13: 13221.419 | CG13: 13152.455 | CH13: 14321.043 | CI13: 13051.323 | CJ13: 13989.347 | CK13: 16147.244 | CL13: 14921.64 | CM13: 15666.104 | CN13: 15715.307 | CO13: 14775.599
A14: Mendoza | B14: 2654.6071 | C14: 3322.7704 | D14: 3379.5221 | E14: 3022.0492 | F14: 3191.0418 | G14: 3125.7417 | H14: 3148.6822 | I14: 3615.5066 | J14: 3658.5221 | K14: 3480.1549 | L14: 3662.2591 | M14: 3593.6653 | N14: 3701.5021 | O14: 5089.1465 | P14: 4064.999 | Q14: 3445.0553 | R14: 3273.5088 | S14: 3605.0188 | T14: 3709.079 | U14: 4420.6864 | V14: 4004.3499 | W14: 4080.6743 | X14: 4550.3858 | Y14: 4707.8059 | Z14: 5153.2849 | AA14: 6384.4011 | AB14: 6281.7492 | AC14: 6010.95 | AD14: 5585.4488 | AE14: 6017.1139 | AF14: 6265.1644 | AG14: 6622.0224 | AH14: 6897.8879 | AI14: 6678.0753 | AJ14: 7418.4775 | AK14: 8481.6238 | AL14: 8315.8929 | AM14: 10093.343 | AN14: 9715.249 | AO14: 10209.087 | AP14: 10769.665 | AQ14: 10775.755 | AR14: 12089.386 | AS14: 13337.815 | AT14: 13523.055 | AU14: 13594.322 | AV14: 14914.458 | AW14: 15838.626 | AX14: 17219.976 | AY14: 20566.551 | AZ14: 21463.657 | BA14: 21220.149 | BB14: 23380.122 | BC14: 24235.459 | BD14: 27218.895 | BE14: 29857.767 | BF14: 33308.182 | BG14: 38692.511 | BH14: 41831.861 | BI14: 44472.629 | BJ14: 54795.948 | BK14: 67755.375 | BL14: 75632.75 | BM14: 71490.94 | BN14: 80071.236 | BO14: 80663.272 | BP14: 83780.008 | BQ14: 89205.702 | BR14: 92967.374 | BS14: 96482.881 | BT14: 100939.29 | BU14: 101478.45 | BV14: 99612.37 | BW14: 117091.6 | BX14: 113045.83 | BY14: 102462.79 | BZ14: 113545.11 | CA14: 110298.34 | CB14: 116828.98 | CC14: 122983.91 | CD14: 125257.87 | CE14: 127969.26 | CF14: 130521.33 | CG14: 130858.37 | CH14: 137448.57 | CI14: 153257.68 | CJ14: 149737.47 | CK14: 138062.47 | CL14: 145745.16 | CM14: 143398.87 | CN14: 147533.95 | CO14: 149688.89
A15: Misiones | B15: 1480.2683 | C15: 1513.478 | D15: 1392.8079 | E15: 1402.2777 | F15: 1520.2131 | G15: 1549.1988 | H15: 1478.6473 | I15: 1620.6925 | J15: 1626.4598 | K15: 1721.9429 | L15: 1841.3363 | M15: 1766.4831 | N15: 1962.418 | O15: 2266.4886 | P15: 1993.6013 | Q15: 1905.6274 | R15: 2406.4604 | S15: 2702.7676 | T15: 3113.6007 | U15: 3446.1132 | V15: 3268.8012 | W15: 3597.3952 | X15: 3669.3059 | Y15: 3793.1739 | Z15: 4137.5955 | AA15: 4293.601 | AB15: 4394.5662 | AC15: 4967.25 | AD15: 5094.1183 | AE15: 5110.316 | AF15: 5193.5204 | AG15: 5631.2113 | AH15: 6176.4508 | AI15: 6254.6697 | AJ15: 6428.9127 | AK15: 6915.4541 | AL15: 7241.4572 | AM15: 7049.0316 | AN15: 7508.7817 | AO15: 7936.4076 | AP15: 8887.8761 | AQ15: 9617.4843 | AR15: 10219.603 | AS15: 11878.068 | AT15: 12088.429 | AU15: 12131.393 | AV15: 12777.584 | AW15: 13284.126 | AX15: 14172.4 | AY15: 15869.1 | AZ15: 16362.9 | BA15: 16035.1 | BB15: 16961 | BC15: 18533.3 | BD15: 20564.7 | BE15: 24140.8 | BF15: 26029 | BG15: 26223.8 | BH15: 33003.2 | BI15: 38596.5 | BJ15: 45758.197 | BK15: 48111.828 | BL15: 53805.048 | BM15: 57990.191 | BN15: 62161.007 | BO15: 62669.792 | BP15: 65271.246 | BQ15: 74516.346 | BR15: 75467.737 | BS15: 75452.259 | BT15: 77168.52 | BU15: 79512.994 | BV15: 91833.114 | BW15: 84330.22 | BX15: 76553.607 | BY15: 80157.211 | BZ15: 88113.926 | CA15: 86813.425 | CB15: 84082.122 | CC15: 86997.915 | CD15: 81349.013 | CE15: 87335.35 | CF15: 87803.655 | CG15: 86665.551 | CH15: 93313.183 | CI15: 85852.995 | CJ15: 82709.365 | CK15: 93488.756 | CL15: 89293.354 | CM15: 88136.544 | CN15: 93773.817 | CO15: 91239.595
A16: Neuquén | B16: 2847.4762 | C16: 2198.2564 | D16: 2389.17 | E16: 2501.5693 | F16: 3397.3829 | G16: 2806.659 | H16: 3277.3562 | I16: 3533.0431 | J16: 3232.3335 | K16: 3582.9735 | L16: 3765.3136 | M16: 3632.8056 | N16: 3652.7278 | O16: 3789.6034 | P16: 3197.7555 | Q16: 2987.9174 | R16: 2345.2243 | S16: 2165.6041 | T16: 3152.1708 | U16: 3138.0957 | V16: 3026.6374 | W16: 3238.5784 | X16: 3635.7763 | Y16: 3717.5496 | Z16: 4896.8663 | AA16: 4505.6971 | AB16: 4919.055 | AC16: 5155.3307 | AD16: 4798.8317 | AE16: 5290.8628 | AF16: 6054.5973 | AG16: 6318.0631 | AH16: 6670.4582 | AI16: 6229.6581 | AJ16: 6420.1347 | AK16: 7050.432 | AL16: 7596.4672 | AM16: 6853.6995 | AN16: 7141.2996 | AO16: 8415.2639 | AP16: 9190.6054 | AQ16: 9241.1376 | AR16: 11770.33 | AS16: 12079.551 | AT16: 12490.249 | AU16: 12909.354 | AV16: 13437.24 | AW16: 14485.159 | AX16: 17989.949 | AY16: 16263.377 | AZ16: 17372.569 | BA16: 19718.766 | BB16: 21772.379 | BC16: 22384.366 | BD16: 26519.098 | BE16: 30087.603 | BF16: 32118.478 | BG16: 38637.34 | BH16: 36487.845 | BI16: 37463.526 | BJ16: 68141.755 | BK16: 72565.317 | BL16: 76596.929 | BM16: 80629.471 | BN16: 90127.321 | BO16: 94216.896 | BP16: 104523.02 | BQ16: 108190.68 | BR16: 125091.58 | BS16: 111713.51 | BT16: 112021.56 | BU16: 110011.13 | BV16: 132242.29 | BW16: 122427.88 | BX16: 116394.98 | BY16: 129950.94 | BZ16: 133207.99 | CA16: 145088.73 | CB16: 156773.09 | CC16: 160819.83 | CD16: 168670.01 | CE16: 164219.27 | CF16: 151340.88 | CG16: 164624 | CH16: 176997.61 | CI16: 176514.96 | CJ16: 157384.82 | CK16: 184224.44 | CL16: 204479.09 | CM16: 209871.28 | CN16: 230324.97
A17: Río Negro | B17: 1324.6566 | C17: 1630.9028 | D17: 1147.2546 | E17: 1184.4538 | F17: 1232.1657 | G17: 1178.3371 | H17: 1207.8689 | I17: 1343.7965 | J17: 1375.5198 | K17: 1442.3703 | L17: 1411.0966 | M17: 1523.2278 | N17: 1967.1774 | O17: 2124.791 | P17: 1555.6569 | Q17: 1121.9924 | R17: 1102.4436 | S17: 1203.6253 | T17: 1383.9471 | U17: 1505.5717 | V17: 1512.4649 | W17: 1642.3343 | X17: 1756.3908 | Y17: 1799.876 | Z17: 2303.9671 | AA17: 2861.5173 | AB17: 2442.834 | AC17: 2455.16 | AD17: 2176.7806 | AE17: 2125.3813 | AF17: 2452.8934 | AG17: 2565.2607 | AH17: 2524.1343 | AI17: 2660.6238 | AJ17: 2984.3764 | AK17: 3098.2916 | AL17: 3829.288 | AM17: 3949.2045 | AN17: 4286.2149 | AO17: 4039.2685 | AP17: 3849.4799 | AQ17: 3700.9794 | AR17: 4262.6681 | AS17: 4639.4309 | AT17: 5160.9727 | AU17: 5037.6942 | AV17: 5366.5947 | AW17: 5901.9457 | AX17: 7422.8277 | AY17: 8379.237 | AZ17: 9093.9017 | BA17: 8293.4907 | BB17: 8567.7953 | BC17: 8269.2981 | BD17: 9659.455 | BE17: 10700.479 | BF17: 11783.723 | BG17: 12694.526 | BH17: 13606.076 | BI17: 15763.067 | BJ17: 25163.55 | BK17: 31350.646 | BL17: 25534.959 | BM17: 27150.845 | BN17: 29778.764 | BO17: 32854.673 | BP17: 36882.722 | BQ17: 38731.261 | BR17: 40089.187 | BS17: 37685.792 | BT17: 40433.11 | BU17: 44826.245 | BV17: 56473.51 | BW17: 67540.94 | BX17: 51236.451 | BY17: 48664.985 | BZ17: 57412.027 | CA17: 55193.543 | CB17: 57388.885 | CC17: 62748.163 | CD17: 62074.632 | CE17: 61885.414 | CF17: 59364.521 | CG17: 66532.219 | CH17: 83827.531 | CI17: 89190.592 | CJ17: 76099.696 | CK17: 71811.17 | CL17: 71599.65 | CM17: 75539.21 | CN17: 82330.258 | CO17: 82280.402
A18: Salta | B18: 1169.3478 | C18: 1180.7292 | D18: 1159.9322 | E18: 1347.6971 | F18: 1382.4959 | G18: 1500.9623 | H18: 1556.5573 | I18: 1714.0148 | J18: 1825.2967 | K18: 1715.7606 | L18: 1880.8625 | M18: 1774.0141 | N18: 2014.8081 | O18: 1839.4487 | P18: 1826.4339 | Q18: 1388.7376 | R18: 1502.8299 | S18: 1677.6969 | T18: 1910.0837 | U18: 2137.0215 | V18: 2095.7213 | W18: 2319.4423 | X18: 2328.1058 | Y18: 2296.1676 | Z18: 2652.2477 | AA18: 2518.1085 | AB18: 2703.4356 | AC18: 2859.9441 | AD18: 2963.9705 | AE18: 3306.7585 | AF18: 3452.2351 | AG18: 4089.3783 | AH18: 4442.9781 | AI18: 4259.0914 | AJ18: 4231.4443 | AK18: 4145.0579 | AL18: 4270.9328 | AM18: 4042.7792 | AN18: 4407.606 | AO18: 5043.1777 | AP18: 5449.4522 | AQ18: 5947.5891 | AR18: 6682.0587 | AS18: 7953.6279 | AT18: 7774.6873 | AU18: 7939.0715 | AV18: 8316.0494 | AW18: 8192.6316 | AX18: 9600.8137 | AY18: 8902.9495 | AZ18: 10014.578 | BA18: 11314.803 | BB18: 12098.695 | BC18: 13092.791 | BD18: 16046.504 | BE18: 16992.156 | BF18: 19306.971 | BG18: 20990.408 | BH18: 24611.026 | BI18: 26229.64 | BJ18: 33077.479 | BK18: 35302.056 | BL18: 39916.41 | BM18: 45554.015 | BN18: 46481.372 | BO18: 44885.462 | BP18: 49807.082 | BQ18: 54930.063 | BR18: 60139.648 | BS18: 57731.78 | BT18: 58592.867 | BU18: 55505.783 | BV18: 60153.134 | BW18: 55472.584 | BX18: 54063.231 | BY18: 57345.301 | BZ18: 62962.882 | CA18: 59418.651 | CB18: 64443.2 | CC18: 72990.569 | CD18: 69516.544 | CE18: 70108.174 | CF18: 70935.287 | CG18: 68239.04 | CH18: 74925.56 | CI18: 69849.51 | CJ18: 65839.419 | CK18: 73188.314 | CL18: 73484.371 | CM18: 72664.727
A19: San Juan | B19: 624.80101 | C19: 634.31884 | D19: 758.96051 | E19: 773.9022 | F19: 679.81375 | G19: 723.32116 | H19: 701.46833 | I19: 787.23358 | J19: 769.26413 | K19: 773.88586 | L19: 848.53484 | M19: 784.8808 | N19: 887.89424 | O19: 828.19658 | P19: 815.3803 | Q19: 861.71881 | R19: 926.35448 | S19: 868.02105 | T19: 902.53426 | U19: 924.31605 | V19: 908.82817 | W19: 983.87271 | X19: 1032.4924 | Y19: 1154.1002 | Z19: 1225.7036 | AA19: 1350.9958 | AB19: 1616.8804 | AC19: 1479.7234 | AD19: 1341.365 | AE19: 1499.8688 | AF19: 1602.015 | AG19: 1657.4475 | AH19: 1746.5789 | AI19: 1778.6048 | AJ19: 1853.5328 | AK19: 1818.6748 | AL19: 2010.0601 | AM19: 2042.3951 | AN19: 2777.6215 | AO19: 2361.9243 | AP19: 2462.1237 | AQ19: 2519.801 | AR19: 2974.9862 | AS19: 3092.356 | AT19: 3105.578 | AU19: 3176.9232 | AV19: 3357.2242 | AW19: 3524.5798 | AX19: 4043.4619 | AY19: 4224.1914 | AZ19: 5647.8691 | BA19: 4904.0509 | BB19: 5456.5434 | BC19: 5713.4857 | BD19: 6280.174 | BE19: 6625.0438 | BF19: 7438.5272 | BG19: 8439.4702 | BH19: 9086.3296 | BI19: 9897.5559 | BJ19: 12437.58 | BK19: 13552.964 | BL19: 14498.824 | BM19: 15480.849 | BN19: 20766.798 | BO19: 17598.517 | BP19: 19490.157 | BQ19: 19606.065 | BR19: 19369.609 | BS19: 19394.879 | BT19: 20375.342 | BU19: 20368.915 | BV19: 22974.744 | BW19: 23126.546 | BX19: 22596.199 | BY19: 25763.443 | BZ19: 29749.597 | CA19: 26396.141 | CB19: 26741.253 | CC19: 28027.663 | CD19: 27990.36 | CE19: 29273.654 | CF19: 28915.158 | CG19: 30939.242 | CH19: 32832.145 | CI19: 31578.629 | CJ19: 31134.188 | CK19: 37756.975 | CL19: 33619.391 | CM19: 34316.313 | CN19: 33374.642 | CO19: 34548.322
A20: San Luis | B20: 640.84076 | C20: 636.35216 | D20: 667.91843 | E20: 702.29081 | F20: 727.32579 | G20: 719.5851 | H20: 709.35345 | I20: 789.21072 | J20: 829.84698 | K20: 806.72742 | L20: 865.1503 | M20: 871.31841 | N20: 864.45254 | O20: 859.14729 | P20: 872.82511 | Q20: 671.99665 | R20: 728.25907 | S20: 995.35299 | T20: 1118.7686 | U20: 1055.1459 | V20: 975.98267 | W20: 1030.7814 | X20: 1069.6848 | Y20: 1169.4418 | Z20: 1336.9945 | AA20: 1246.1036 | AB20: 1416.9746 | AC20: 1526.8476 | AD20: 1444.4712 | AE20: 1528.5914 | AF20: 1686.4183 | AG20: 1770.4807 | AH20: 1763.5369 | AI20: 1792.4366 | AJ20: 1927.445 | AK20: 2019.2871 | AL20: 2134.2494 | AM20: 2100.7482 | AN20: 2636.72 | AO20: 2448.9312 | AP20: 2629.0623 | AQ20: 2702.3342 | AR20: 2962.7803 | AS20: 3078.1382 | AT20: 3419.7188 | AU20: 3367.9164 | AV20: 3641.9455 | AW20: 3678.5025 | AX20: 4054.6082 | AY20: 4672.7675 | AZ20: 5217.8634 | BA20: 4894.6575 | BB20: 5501.2707 | BC20: 5720.6009 | BD20: 6243.6704 | BE20: 6995.7925 | BF20: 7680.6667 | BG20: 7997.6061 | BH20: 9435.7048 | BI20: 10081.01 | BJ20: 12959.623 | BK20: 13909.493 | BL20: 18170.129 | BM20: 15923.332 | BN20: 18843.292 | BO20: 18484.995 | BP20: 20395.358 | BQ20: 20969.095 | BR20: 20875.737 | BS20: 21055.384 | BT20: 23009.467 | BU20: 23846.132 | BV20: 25661.234 | BW20: 25455.286 | BX20: 31012.033 | BY20: 24380.004 | BZ20: 26158.692 | CA20: 26438.972 | CB20: 28621.589 | CC20: 29151.964 | CD20: 28235.575 | CE20: 28739.312 | CF20: 30341.148 | CG20: 32192.86 | CH20: 32925.768 | CI20: 42241.453 | CJ20: 35732.659 | CK20: 33109.847 | CL20: 33714.644 | CM20: 34436.175 | CN20: 35822.841 | CO20: 37869.764
A21: Santa Cruz | B21: 849.99489 | C21: 807.43581 | D21: 806.54163 | E21: 877.75055 | F21: 968.35065 | G21: 933.33398 | H21: 934.31273 | I21: 1010.1422 | J21: 1001.4313 | K21: 1088.611 | L21: 1216.7367 | M21: 1159.978 | N21: 1226.7127 | O21: 1144.8662 | P21: 1046.4484 | Q21: 1020.4459 | R21: 811.44042 | S21: 740.60141 | T21: 915.22951 | U21: 1072.242 | V21: 1000.5976 | W21: 1162.8907 | X21: 1331.9159 | Y21: 1164.0634 | Z21: 1487.033 | AA21: 1355.6979 | AB21: 1479.0204 | AC21: 1701.2 | AD21: 1703.8889 | AE21: 1741.8349 | AF21: 1849.8895 | AG21: 2066.0477 | AH21: 2106.2826 | AI21: 2180.9836 | AJ21: 2299.1607 | AK21: 2438.8117 | AL21: 2613.7678 | AM21: 2443.8599 | AN21: 2591.3146 | AO21: 2807.9053 | AP21: 2820.3012 | AQ21: 3085.925 | AR21: 3528.67 | AS21: 3629.0506 | AT21: 3886.4423 | AU21: 3811.6051 | AV21: 4215.6751 | AW21: 4727.0807 | AX21: 5210.8828 | AY21: 4789.7818 | AZ21: 5630.9383 | BA21: 6094.3916 | BB21: 6832.6816 | BC21: 6749.6946 | BD21: 8297.3041 | BE21: 8161.3727 | BF21: 8055.354 | BG21: 10539.688 | BH21: 10620.238 | BI21: 11303.645 | BJ21: 16792.703 | BK21: 19241.012 | BL21: 20136.528 | BM21: 21451.646 | BN21: 22735.282 | BO21: 23281.262 | BP21: 24987.495 | BQ21: 25073.661 | BR21: 25940.614 | BS21: 27900.631 | BT21: 30094.342 | BU21: 28737.455 | BV21: 33072.018 | BW21: 31133.807 | BX21: 29451.352 | BY21: 29573.809 | BZ21: 32518.858 | CA21: 30020.014 | CB21: 31220.256 | CC21: 31945.6 | CD21: 31228.14 | CE21: 32420.4 | CF21: 32767.792 | CG21: 35314.14 | CH21: 47808.716 | CI21: 37598.47 | CJ21: 34312.263 | CK21: 39377.533 | CL21: 38356.291 | CM21: 40858.736 | CN21: 39842.874
A22: Santa Fe | B22: 4921.3025 | C22: 5760.2067 | D22: 4968.673 | E22: 5498.7 | F22: 5682.0237 | G22: 5855.9942 | H22: 5752.9442 | I22: 6535.8314 | J22: 6803.2927 | K22: 6872.25 | L22: 7493.72 | M22: 7630.89 | N22: 7303.41 | O22: 8487.59 | P22: 6785.33 | Q22: 6211.6 | R22: 7621.62 | S22: 8479.99 | T22: 9269.6 | U22: 9522.31 | V22: 9339.33 | W22: 9712.71 | X22: 10446.21 | Y22: 9729.4 | Z22: 10405.9 | AA22: 11997.46 | AB22: 11015.29 | AC22: 12087.11 | AD22: 12872.72 | AE22: 13612.13 | AF22: 13703.47 | AG22: 14639.97 | AH22: 15087.14 | AI22: 15041.5 | AJ22: 16231.61 | AK22: 16582.57 | AL22: 17128.26 | AM22: 19320.41 | AN22: 16990.7 | AO22: 20315.44 | AP22: 21892.17 | AQ22: 23869.87 | AR22: 25461.74 | AS22: 25306.53 | AT22: 27818.61 | AU22: 28235.36 | AV22: 28738.52 | AW22: 30029.39 | AX22: 33505.64 | AY22: 34595.31 | AZ22: 32866.64 | BA22: 38067.11 | BB22: 42822.64 | BC22: 47774.76 | BD22: 51834.63 | BE22: 59777.14 | BF22: 64496.04 | BG22: 72110 | BH22: 73683.07 | BI22: 83901.76 | BJ22: 106788.38 | BK22: 134048.33 | BL22: 129467.99 | BM22: 137584.51 | BN22: 148510.33 | BO22: 161375.98 | BP22: 157982.29 | BQ22: 177315.62 | BR22: 175714.89 | BS22: 178323.16 | BT22: 187379.75 | BU22: 186458.83 | BV22: 199786.57 | BW22: 255361.88 | BX22: 185401.09 | BY22: 208889.45 | BZ22: 225377.43 | CA22: 245665.02 | CB22: 247964.69 | CC22: 262128.22 | CD22: 259248.81 | CE22: 273435.86 | CF22: 248247.24 | CG22: 269893.68 | CH22: 288132.28 | CI22: 335060.31 | CJ22: 249503.32 | CK22: 282238.89 | CL22: 284533.49 | CM22: 299750.13
A23: S del Estero | B23: s.d | C23: s.d | D23: s.d | E23: s.d | F23: s.d | G23: s.d | H23: s.d | I23: s.d | J23: s.d | K23: s.d | L23: s.d | M23: s.d | N23: s.d | O23: s.d | P23: s.d | Q23: s.d | R23: s.d | S23: s.d | T23: s.d | U23: s.d | V23: s.d | W23: s.d | X23: s.d | Y23: s.d | Z23: s.d | AA23: s.d | AB23: s.d | AC23: s.d | AD23: s.d | AE23: s.d | AF23: s.d | AG23: s.d | AH23: s.d | AI23: s.d | AJ23: s.d | AK23: s.d | AL23: s.d | AM23: s.d | AN23: s.d | AO23: s.d | AP23: s.d | AQ23: s.d | AR23: s.d | AS23: s.d | AT23: s.d | AU23: s.d | AV23: s.d | AW23: s.d | AX23: s.d | AY23: s.d | AZ23: s.d | BA23: s.d | BB23: s.d | BC23: s.d | BD23: s.d | BE23: s.d | BF23: s.d | BG23: s.d | BH23: s.d | BI23: s.d | BJ23: 8637.7424 | BK23: 9088.315 | BL23: 11660.467 | BM23: 14113.68 | BN23: 12627.862 | BO23: 13461.319 | BP23: 14749.431 | BQ23: 16256.543 | BR23: 16017.26 | BS23: 16107.5 | BT23: 16601.347 | BU23: 15645.963 | BV23: 17611.473 | BW23: 16014.462 | BX23: 17564.563 | BY23: 23719.965 | BZ23: 20976.25 | CA23: 22887.981 | CB23: 22913.608 | CC23: 22997.61 | CD23: 23019.522 | CE23: 23365.747 | CF23: 24845.041 | CG23: 22468.189 | CH23: 22738.897 | CI23: 20785.314 | CJ23: 25819.087 | CK23: 25556.922 | CL23: 30433.307 | CM23: 33878.883 | CN23: 33131.057 | CO23: 33821.176
A24: T del Fuego (*) | B24: 625.55052 | C24: 576.50045 | D24: 586.55123 | E24: 650.16713 | F24: 772.20188 | G24: 739.195 | H24: 735.18119 | I24: 741.42718 | J24: 797.67061 | K24: 790.56721 | L24: 862.37536 | M24: 805.05644 | N24: 867.5939 | O24: 828.52706 | P24: 790.14487 | Q24: 689.00155 | R24: 611.94784 | S24: 656.48293 | T24: 884.90572 | U24: 977.91507 | V24: 873.52159 | W24: 990.6942 | X24: 1096.1613 | Y24: 1174.6507 | Z24: 1326.1786 | AA24: 1205.9375 | AB24: 1287.7756 | AC24: 1497.6125 | AD24: 1431.8482 | AE24: 1511.8194 | AF24: 1665.6452 | AG24: 1865.7085 | AH24: 1847.2545 | AI24: 1787.3311 | AJ24: 1802.9497 | AK24: 1874.406 | AL24: 2089.4679 | AM24: 1786.8782 | AN24: 2008.6057 | AO24: 2494.8662 | AP24: 2452.5334 | AQ24: 2804.8902 | AR24: 3375.1214 | AS24: 3755.8194 | AT24: 3731.2278 | AU24: 3800.783 | AV24: 4267.7803 | AW24: 4524.2019 | AX24: 4780.4506 | AY24: 4160.3351 | AZ24: 4840.4558 | BA24: 6042.6151 | BB24: 6048.9815 | BC24: 6623.9434 | BD24: 7311.3124 | BE24: 7501.8487 | BF24: 8821.3148 | BG24: 9686.1069 | BH24: 10597.438 | BI24: 12310.833 | BJ24: 16562.917 | BK24: 14576.969 | BL24: 18545.146 | BM24: 18102.227 | BN24: 19993.717 | BO24: 21753.985 | BP24: 20916.575 | BQ24: 22367.346 | BR24: 24616.707 | BS24: 25199.98 | BT24: 27206.946 | BU24: 27768.459 | BV24: 29302.327 | BW24: 26827.821 | BX24: 24989.308 | BY24: 27317.3 | BZ24: 30893.886 | CA24: 29427.94 | CB24: 32430.7 | CC24: 33432.427 | CD24: 33530.629 | CE24: 33399.683 | CF24: 35175.751 | CG24: 34812.607 | CH24: 35478.823 | CI24: 32414.294 | CJ24: 30776.875 | CK24: 37829.61 | CL24: 33557.705 | CM24: 33641.508 | CN24: 36095.924
A25: Tucumán | B25: 2042.2358 | C25: 1842.1003 | D25: 1761.4918 | E25: 1878.4967 | F25: 2056.1688 | G25: 2090.8605 | H25: 2249.4845 | I25: 2322.9863 | J25: 2463.0177 | K25: 2416.7359 | L25: 2712.6444 | M25: 3043.9577 | N25: 2765.123 | O25: 2497.9383 | P25: 2288.2566 | Q25: 2176.6809 | R25: 2441.0117 | S25: 2824.9666 | T25: 3187.9319 | U25: 3427.0867 | V25: 3440.1186 | W25: 3553.0282 | X25: 3935.0517 | Y25: 4485.888 | Z25: 4434.9257 | AA25: 3753.8946 | AB25: 3932.1433 | AC25: 4433.53 | AD25: 4465.7784 | AE25: 4695.5697 | AF25: 5171.1005 | AG25: 5476.3087 | AH25: 5651.9201 | AI25: 5769.9976 | AJ25: 6248.1046 | AK25: 7295.4465 | AL25: 6950.9364 | AM25: 6048.3703 | AN25: 6274.2918 | AO25: 7192.6058 | AP25: 7563.511 | AQ25: 7979.0603 | AR25: 9011.316 | AS25: 9387.1646 | AT25: 9969.8286 | AU25: 10295.672 | AV25: 10648.308 | AW25: 13274.267 | AX25: 13069.086 | AY25: 11378.782 | AZ25: 12266.376 | BA25: 14213.82 | BB25: 15271.137 | BC25: 16486.54 | BD25: 19141.663 | BE25: 20200.321 | BF25: 23047.57 | BG25: 25156.314 | BH25: 28553.301 | BI25: 36142.628 | BJ25: 43555.212 | BK25: 39529.55 | BL25: 42757.624 | BM25: 49224.406 | BN25: 53079.654 | BO25: 57333.891 | BP25: 61928.024 | BQ25: 68229.638 | BR25: 72408.153 | BS25: 69081.351 | BT25: 75508.176 | BU25: 89918.356 | BV25: 85679.582 | BW25: 81197.041 | BX25: 77532.501 | BY25: 82896.196 | BZ25: 93092.75 | CA25: 94603.825 | CB25: 95086.641 | CC25: 101175.32 | CD25: 99535.542 | CE25: 99884.006 | CF25: 104674.96 | CG25: 113442.59 | CH25: 113499.02 | CI25: 99218.207 | CJ25: 97740.315 | CK25: 107722.41 | CL25: 110446.52 | CM25: 115179.08 | CN25: 122017
A26: TOTAL | B26: =SUM(B2:B25) -> 79681.644 | C26: =SUM(C2:C25) -> 79546.943 | D26: =SUM(D2:D25) -> 74031.122 | E26: =SUM(E2:E25) -> 77120.032 | F26: =SUM(F2:F25) -> 80979.263 | G26: =SUM(G2:G25) -> 82253.392 | H26: =SUM(H2:H25) -> 83102.227 | I26: =SUM(I2:I25) -> 89132.506 | ... CO26: =SUM(CO2:CO25) -> 2165916.8
A28: (*) Excluye regalías y derechos
A29: -valores expresados en millones de pesos corrientes-

Sheet II.BB
A1: JURISDICCIÓN | B1: 43466 | C1: 43497 | D1: 43525 | E1: 43556 | F1: 43586 | G1: 43617 | H1: 43647 | I1: 43678 | J1: 43709 | K1: 43739 | L1: 43770 | M1: 43800 | N1: 43831 | O1: 43862 | P1: 43891 | Q1: 43922 | R1: 43952 | S1: 43983 | T1: 44013 | U1: 44044 | V1: 44075 | W1: 44105 | X1: 44136 | Y1: 44166 | Z1: 44197 | AA1: 44228 | AB1: 44256 | AC1: 44287 | AD1: 44317 | AE1: 44348 | AF1: 44378 | AG1: 44409 | AH1: 44440 | AI1: 44470 | AJ1: 44501 | AK1: 44531 | AL1: 44562 | AM1: 44593 | AN1: 44621 | AO1: 44652 | AP1: 44682 | AQ1: 44713 | AR1: 44743 | AS1: 44774 | AT1: 44805 | AU1: 44835 | AV1: 44866 | AW1: 44896 | AX1: 44927 | AY1: 44958 | AZ1: 44986 | BA1: 45017 | BB1: 45047 | BC1: 45078 | BD1: 45108 | BE1: 45139 | BF1: 45170 | BG1: 45200 | BH1: 45231 | BI1: 45261 | BJ1: 45292 | BK1: 45323 | BL1: 45352 | BM1: 45383 | BN1: 45413 | BO1: 45444 | BP1: 45474 | BQ1: 45505 | BR1: 45536 | BS1: 45566 | BT1: 45597 | BU1: 45627 | BV1: 45658 | BW1: 45689 | BX1: 45717 | BY1: 45748 | BZ1: 45778 | CA1: 45809 | CB1: 45839 | CC1: 45870 | CD1: 45901 | CE1: 45931 | CF1: 45962 | CG1: 45992 | CH1: 46023 | CI1: 46054 | CJ1: 46082 | CK1: 46113 | CL1: 46143 | CM1: 46174 | CN1: 46204 | CO1: 46235
A2: Buenos Aires | B2: 19469.166 | C2: 18898.826 | D2: 17247.554 | E2: 19007.616 | F2: 19997.073 | G2: 20764.925 | H2: 21109.04 | I2: 23213.452 | J2: 24704.742 | K2: 25008.428 | L2: 27422.261 | M2: 25760.82 | N2: 28806.982 | O2: 25918.916 | P2: 24830.795 | Q2: 22536.703 | R2: 23607.658 | S2: 25474.007 | T2: 28422.813 | U2: 30114.947 | V2: 29651.683 | W2: 31136.659 | X2: 32220.772 | Y2: 36363.885 | Z2: 39904.639 | AA2: 37375.089 | AB2: 39910.55 | AC2: 45490.535 | AD2: 44892.717 | AE2: 48785.995 | AF2: 50894.686 | AG2: 47018.9 | AH2: 48281.049 | AI2: 55248.688 | AJ2: 60270.927 | AK2: 61099.982 | AL2: 63607.762 | AM2: 59649.701 | AN2: 65658.817 | AO2: 74722.879 | AP2: 80183.053 | AQ2: 86689.81 | AR2: 98074.046 | AS2: 95519.718 | AT2: 102564.63 | AU2: 109297.35 | AV2: 108270.45 | AW2: 115200.19 | AX2: 130799.78 | AY2: 119237.94 | AZ2: 135057.13 | BA2: 153197.93 | BB2: 165554.97 | BC2: 180109.11 | BD2: 199092.82 | BE2: 215351.83 | BF2: 242939.43 | BG2: 274312.92 | BH2: 296861.21 | BI2: 311681.97 | BJ2: 428334.41 | BK2: 486570.59 | BL2: 645347.35 | BM2: 568904.97 | BN2: 536788.27 | BO2: 574402.55 | BP2: 624934.46 | BQ2: 660303.14 | BR2: 680231.72 | BS2: 732376.8 | BT2: 754880 | BU2: 756716.28 | BV2: 801028.68 | BW2: 766738.37 | BX2: 730649.2 | BY2: 829273.77 | BZ2: 872228.19 | CA2: 860880.74 | CB2: 907341.99 | CC2: 940605.7 | CD2: 950550.07 | CE2: 992273.79 | CF2: 948570.5 | CG2: 1031334 | CH2: 1086193.5 | CI2: 961709.43 | CJ2: 944164.54 | CK2: 1084984.7 | CL2: 1060147.3 | CM2: 1156260.9 | CN2: 1197577.6
A3: CABA | B3: 12611.1 | C3: 12684.1 | D3: 11368.4 | E3: 13211.1 | F3: 13541.2 | G3: 13649 | H3: 14401.2 | I3: 15210.6 | J3: 16472.6 | K3: 16296.7 | L3: 18612.5 | M3: 17845.3 | N3: 18761.5 | O3: 18499 | P3: 16493.2 | Q3: 14973.8 | R3: 16776.5 | S3: 17490.4 | T3: 19183.7 | U3: 21037.2 | V3: 22899.9 | W3: 23675.3 | X3: 23367 | Y3: 23633.5 | Z3: 28177.9 | AA3: 27902.5 | AB3: 26120.9 | AC3: 29916.1 | AD3: 32532 | AE3: 33075.6 | AF3: 34552.8 | AG3: 36424.6 | AH3: 38149.6 | AI3: 39851.4 | AJ3: 42764.9 | AK3: 44439 | AL3: 47378.4 | AM3: 44415 | AN3: 43795.4 | AO3: 52626.5 | AP3: 55637.2 | AQ3: 61207.3 | AR3: 66484.5 | AS3: 71054.9 | AT3: 81030.8 | AU3: 88021.1 | AV3: 92653.8 | AW3: 98795.2 | AX3: 110799.6 | AY3: 106617.9 | AZ3: 107785.1 | BA3: 129864 | BB3: 141849.6 | BC3: 163293.9 | BD3: 182889.2 | BE3: 195182.9 | BF3: 237624.4 | BG3: 262022.6 | BH3: 290128.6 | BI3: 313290 | BJ3: 398009.6 | BK3: 396259.7 | BL3: 410409.2 | BM3: 453180.1 | BN3: 476859.7 | BO3: 492292.3 | BP3: 468321.7 | BQ3: 512970.6 | BR3: 525667.8 | BS3: 510934.1 | BT3: 546517.8 | BU3: 555416.3 | BV3: 594667.9 | BW3: 580377.5 | BX3: 541400 | BY3: 574044 | BZ3: 630408.4 | CA3: 608896.4 | CB3: 620015.6 | CC3: 689753 | CD3: 710053.2 | CE3: 750756.1 | CF3: 767058.3 | CG3: 698779.1 | CH3: 759579.1 | CI3: 711180.3 | CJ3: 644673.9 | CK3: 714719.7 | CL3: 750198.5 | CM3: 737506.4 | CN3: 783413.9 | CO3: 807806.2
A4: Catamarca | B4: 307.42737 | C4: 258.5751 | D4: 259.25183 | E4: 263.531 | F4: 279.23669 | G4: 286.41306 | H4: 280.45173 | I4: 282.48556 | J4: 320.44667 | K4: 374.9298 | L4: 374.80001 | M4: 338.29459 | N4: 352.02712 | O4: 345.53387 | P4: 322.73215 | Q4: 362.72444 | R4: 353.92003 | S4: 397.61475 | T4: 438.82771 | U4: 442.32752 | V4: 439.64684 | W4: 455.3239 | X4: 462.84231 | Y4: 483.73476 | Z4: 554.81843 | AA4: 511.45737 | AB4: 517.09 | AC4: 756.238 | AD4: 582.28471 | AE4: 666.34334 | AF4: 708.16455 | AG4: 772.26718 | AH4: 879.47588 | AI4: 978.05198 | AJ4: 1059.8056 | AK4: 1153.9155 | AL4: 1120.839 | AM4: 1003.7339 | AN4: 1136.5702 | AO4: 1141.7854 | AP4: 1136.2186 | AQ4: 1751.6118 | AR4: 1574.1008 | AS4: 1783.4066 | AT4: 1982.8105 | AU4: 1969.6715 | AV4: 2254.5844 | AW4: 2213.6473 | AX4: 2299.2293 | AY4: 2124.2458 | AZ4: 2397.4896 | BA4: 2873.946 | BB4: 2977.8885 | BC4: 3563.5331 | BD4: 3976.4588 | BE4: 4277.19 | BF4: 4678.59 | BG4: 5202.8621 | BH4: 5665.244 | BI4: 5925.4571 | BJ4: 8099.3865 | BK4: 9398.4259 | BL4: 9122.8777 | BM4: 10327.213 | BN4: 12166.971 | BO4: 12560.388 | BP4: 12002.123 | BQ4: 13283.868 | BR4: 14020.967 | BS4: 14636.624 | BT4: 16753.545 | BU4: 15448.871 | BV4: 16993.488 | BW4: 14805.802 | BX4: 13729.718 | BY4: 14536.52 | BZ4: 16392.718 | CA4: 16548.907 | CB4: 16806.7 | CC4: 16999.969 | CD4: 18224.408 | CE4: 19430.392 | CF4: 18632.348 | CG4: 17712.051 | CH4: 21870.152 | CI4: 18769 | CJ4: 18127.227 | CK4: 20732.331 | CL4: 20529.255 | CM4: 21657.433 | CN4: 23144.821 | CO4: 21835.974
A5: Chaco | B5: 680.98036 | C5: 605.51695 | D5: 574.96754 | E5: 606.6499 | F5: 646.71323 | G5: 652.94039 | H5: 708.46933 | I5: 743.43347 | J5: 871.49433 | K5: 778.55945 | L5: 842.19981 | M5: 813.35473 | N5: 1073.237 | O5: 923.40167 | P5: 784.63262 | Q5: 776.87912 | R5: 842.87909 | S5: 957.2402 | T5: 1000.2268 | U5: 1069.4389 | V5: 1038.7728 | W5: 1106.6568 | X5: 1210.8388 | Y5: 1181.9563 | Z5: 1392.4639 | AA5: 1248.6747 | AB5: 1368.1387 | AC5: 1489.9431 | AD5: 1542.0669 | AE5: 1641.9167 | AF5: 1852.7481 | AG5: 1915.947 | AH5: 1921.1024 | AI5: 2006.7133 | AJ5: 2106.5333 | AK5: 2197.1867 | AL5: 2185.4968 | AM5: 2115.6565 | AN5: 2303.1269 | AO5: 2533.8572 | AP5: 2905.584 | AQ5: 3125.9102 | AR5: 3416.1621 | AS5: 3398.6732 | AT5: 3656.081 | AU5: 4070.1727 | AV5: 4094.6363 | AW5: 4345.042 | AX5: 4815.2899 | AY5: 4369.8693 | AZ5: 4909.5681 | BA5: 5244.8806 | BB5: 6018.307 | BC5: 6520.2592 | BD5: 7024.5221 | BE5: 7659.516 | BF5: 8617.5445 | BG5: 9632.5403 | BH5: 10032.621 | BI5: 10903.555 | BJ5: 12983.344 | BK5: 13864.746 | BL5: 15035.025 | BM5: 15687.871 | BN5: 16771.491 | BO5: 18679.237 | BP5: 20921.794 | BQ5: 22694.275 | BR5: 23462.943 | BS5: 22536.574 | BT5: 24041.583 | BU5: 24483.032 | BV5: 25616.409 | BW5: 24788.698 | BX5: 23561.912 | BY5: 25194.755 | BZ5: 27534.794 | CA5: 27255.336 | CB5: 27201.764 | CC5: 29260.894 | CD5: 28388.437 | CE5: 28379.416 | CF5: 27573.18 | CG5: 30009.018 | CH5: 33654.962 | CI5: 31721.62 | CJ5: 28963.61 | CK5: 30813.302 | CL5: 31627.758 | CM5: 33417.513 | CN5: 36452.558 | CO5: 37011.91
A6: Chubut | B6: 1047 | C6: 912 | D6: 970 | E6: 1050 | F6: 1114 | G6: 987 | H6: 1075 | I6: 1201 | J6: 1187 | K6: 1358 | L6: 1325 | M6: 1178 | N6: 1272 | O6: 1386 | P6: 1259 | Q6: 1112 | R6: 1042 | S6: 1109 | T6: 1024 | U6: 1033 | V6: 1388 | W6: 1563 | X6: 1564 | Y6: 1513 | Z6: 1646 | AA6: 1676 | AB6: 1874 | AC6: 2081 | AD6: 2208 | AE6: 2263 | AF6: 2466 | AG6: 2471 | AH6: 2594 | AI6: 2501 | AJ6: 2619 | AK6: 2665 | AL6: 2789 | AM6: 2583 | AN6: 2833 | AO6: 3141 | AP6: 3168 | AQ6: 3367 | AR6: 4255 | AS6: 4371 | AT6: 4771 | AU6: 4817 | AV6: 5228 | AW6: 5663 | AX6: 6339 | AY6: 6090 | AZ6: 6603 | BA6: 7634 | BB6: 8145 | BC6: 7588 | BD6: 9125 | BE6: 10864 | BF6: 11226 | BG6: 13306 | BH6: 12773 | BI6: 14156 | BJ6: 19579 | BK6: 25294 | BL6: 24254 | BM6: 26344 | BN6: 27852 | BO6: 31547 | BP6: 29177 | BQ6: 29719 | BR6: 30718 | BS6: 32026 | BT6: 34176 | BU6: 34337 | BV6: 36468 | BW6: 36651 | BX6: 35580 | BY6: 36487 | BZ6: 38131 | CA6: 38685 | CB6: 43623 | CC6: 43660 | CD6: 43209 | CE6: 48238 | CF6: 41912 | CG6: 47152 | CH6: 49522 | CI6: 45753 | CJ6: 41764 | CK6: 46964 | CL6: 48912 | CM6: 48360 | CN6: 59118 | CO6: 53052
A7: Córdoba | B7: 4724.8523 | C7: 4415.936 | D7: 4232.203 | E7: 4359.9317 | F7: 4899.523 | G7: 4958.5732 | H7: 5305.4507 | I7: 5995.733 | J7: 6159.4109 | K7: 5999.6791 | L7: 6380.3395 | M7: 6101.8058 | N7: 6870.0771 | O7: 6630.2017 | P7: 5813.6958 | Q7: 5034.0455 | R7: 5831.708 | S7: 6721.624 | T7: 7123.4579 | U7: 7745.6913 | V7: 7770.6759 | W7: 7918.2637 | X7: 8382.8955 | Y7: 8673.7372 | Z7: 9862.7953 | AA7: 9188.0826 | AB7: 9588.1046 | AC7: 10443.763 | AD7: 11070.969 | AE7: 11456.37 | AF7: 12032.041 | AG7: 12992.535 | AH7: 13673.927 | AI7: 13087.088 | AJ7: 14586.356 | AK7: 15062.063 | AL7: 15933.815 | AM7: 14648.5 | AN7: 15465.712 | AO7: 17349.164 | AP7: 19012.68 | AQ7: 20375.356 | AR7: 22465.398 | AS7: 22705.694 | AT7: 24916.884 | AU7: 25867.148 | AV7: 26656.038 | AW7: 27711.15 | AX7: 30554.628 | AY7: 27416.805 | AZ7: 32041.734 | BA7: 35279.341 | BB7: 40880.085 | BC7: 43250.238 | BD7: 47061.638 | BE7: 52469.548 | BF7: 58901.422 | BG7: 67460.218 | BH7: 73545.701 | BI7: 79962.166 | BJ7: 107516.92 | BK7: 119638.22 | BL7: 128619.68 | BM7: 136088.79 | BN7: 144518.97 | BO7: 152684.21 | BP7: 148078.96 | BQ7: 166672.61 | BR7: 173256.41 | BS7: 172976.22 | BT7: 178425.57 | BU7: 175804.95 | BV7: 190808.17 | BW7: 190422.94 | BX7: 178063.54 | BY7: 192924.06 | BZ7: 213969.94 | CA7: 222574.01 | CB7: 238021.17 | CC7: 249001.89 | CD7: 235040.89 | CE7: 241347.14 | CF7: 240638.66 | CG7: 272678.18 | CH7: 277942.44 | CI7: 242946.5 | CJ7: 245101.44 | CK7: 260877.64 | CL7: 272287.85 | CM7: 271632.29 | CN7: 275249.34 | CO7: 281578.51
A8: Corrientes | B8: s.d | C8: s.d | D8: s.d | E8: s.d | F8: s.d | G8: s.d | H8: s.d | I8: s.d | J8: s.d | K8: s.d | L8: s.d | M8: s.d | N8: s.d | O8: s.d | P8: s.d | Q8: s.d | R8: s.d | S8: s.d | T8: s.d | U8: s.d | V8: s.d | W8: s.d | X8: s.d | Y8: s.d | Z8: s.d | AA8: s.d | AB8: s.d | AC8: s.d | AD8: s.d | AE8: s.d | AF8: s.d | AG8: s.d | AH8: s.d | AI8: s.d | AJ8: s.d | AK8: s.d | AL8: s.d | AM8: s.d | AN8: s.d | AO8: s.d | AP8: s.d | AQ8: s.d | AR8: s.d | AS8: s.d | AT8: s.d | AU8: s.d | AV8: s.d | AW8: s.d | AX8: s.d | AY8: s.d | AZ8: s.d | BA8: s.d | BB8: s.d | BC8: s.d | BD8: s.d | BE8: s.d | BF8: s.d | BG8: s.d | BH8: s.d | BI8: s.d | BJ8: 12671.268 | BK8: 13632.62 | BL8: 13724.071 | BM8: 15485.852 | BN8: 17074.205 | BO8: 17057.7 | BP8: 18252.774 | BQ8: 21290.33 | BR8: 21139.724 | BS8: 20759.83 | BT8: 22268.39 | BU8: 22589.46 | BV8: 24615.52 | BW8: 24407 | BX8: 23487.05 | BY8: 24338.75 | BZ8: 26424.023 | CA8: 25520.33 | CB8: 26235.9 | CC8: 28740.941 | CD8: 28345.849 | CE8: 27963.35 | CF8: 27718.066 | CG8: 28412.888 | CH8: 31388.156 | CI8: 30211.81 | CJ8: 28772.438 | CK8: 32059.957 | CL8: 32161.158 | CM8: 32702.152 | CN8: 33839.744
A9: Entre Ríos | B9: 1182.8414 | C9: 1088.5944 | D9: 1073.097 | E9: 1359.4628 | F9: 1328.187 | G9: 1338.0169 | H9: 1299.1336 | I9: 1390.9666 | J9: 1539.6339 | K9: 1576.8085 | L9: 1658.8024 | M9: 1628.2032 | N9: 1750.3163 | O9: 1705.0972 | P9: 1447.9296 | Q9: 1458.8003 | R9: 1616.2937 | S9: 1833.8898 | T9: 1926.9865 | U9: 2105.8489 | V9: 2043.3869 | W9: 2078.2559 | X9: 2258.0421 | Y9: 2226.1139 | Z9: 2652.9075 | AA9: 2611.1443 | AB9: 2496.8154 | AC9: 2932.09 | AD9: 2990.4347 | AE9: 3124.3943 | AF9: 3425.9534 | AG9: 3806.9973 | AH9: 3780.1423 | AI9: 3893.6711 | AJ9: 4060.3784 | AK9: 4207.4135 | AL9: 4635.6097 | AM9: 3968.0219 | AN9: 4096.6458 | AO9: 4755.9931 | AP9: 5004.3612 | AQ9: 5348.0985 | AR9: 6092.7137 | AS9: 6334.6842 | AT9: 6740.8353 | AU9: 7131.4665 | AV9: 7052.7155 | AW9: 7909.2827 | AX9: 8751.8711 | AY9: 7794.2 | AZ9: 8449.2019 | BA9: 9891.5384 | BB9: 10802.385 | BC9: 11295.344 | BD9: 12635.208 | BE9: 14383.858 | BF9: 16381.228 | BG9: 17708.812 | BH9: 19351.116 | BI9: 21764.249 | BJ9: 28907.359 | BK9: 29961.905 | BL9: 32092.847 | BM9: 34857.758 | BN9: 36246.457 | BO9: 38738.123 | BP9: 41956.626 | BQ9: 45053.049 | BR9: 45813.634 | BS9: 43303.916 | BT9: 45549.235 | BU9: 45901.488 | BV9: 50715.334 | BW9: 48686.262 | BX9: 44861.791 | BY9: 48699.626 | BZ9: 54555.993 | CA9: 55341.072 | CB9: 57293.055 | CC9: 59822.863 | CD9: 62267.183 | CE9: 65045.398 | CF9: 61797.567 | CG9: 65711.907 | CH9: 71086.672 | CI9: 64039.056 | CJ9: 61780.307 | CK9: 67785.222 | CL9: 67360.574 | CM9: 71000.46 | CN9: 72164.557 | CO9: 74265.59
A10: Formosa | B10: 226.08144 | C10: 223.59782 | D10: 219.5326 | E10: 243.75641 | F10: 236.48121 | G10: 264.72604 | H10: 257.53739 | I10: 286.61069 | J10: 292.109 | K10: 284.2272 | L10: 315.73895 | M10: 311.58749 | N10: 320.14391 | O10: 317.03713 | P10: 302.68988 | Q10: 268.99388 | R10: 273.83737 | S10: 310.1848 | T10: 342.78029 | U10: 377.1372 | V10: 386.59237 | W10: 412.16155 | X10: 445.99292 | Y10: 474.44584 | Z10: 519.42801 | AA10: 484.96916 | AB10: 591.66243 | AC10: 613.71 | AD10: 630.29768 | AE10: 614.0107 | AF10: 669.41393 | AG10: 787.5279 | AH10: 835.73335 | AI10: 825.57668 | AJ10: 905.03403 | AK10: 904.57667 | AL10: 1052.0291 | AM10: 916.51193 | AN10: 976.98066 | AO10: 1182.7664 | AP10: 1209.4411 | AQ10: 1254.3202 | AR10: 1500.4928 | AS10: 1496.0535 | AT10: 1701.6368 | AU10: 1660.8192 | AV10: 1783.5781 | AW10: 1954.1703 | AX10: 2121.1337 | AY10: 1949.0793 | AZ10: 2182.3796 | BA10: 2390.9285 | BB10: 2614.7556 | BC10: 2833.2773 | BD10: 3233.4496 | BE10: 3601.64 | BF10: 3843.3341 | BG10: 3955.7345 | BH10: 4289.2723 | BI10: 4725.2521 | BJ10: 5363.5279 | BK10: 4944.0414 | BL10: 6180.8701 | BM10: 6094.5293 | BN10: 6930.1318 | BO10: 8103.2007 | BP10: 7683.7572 | BQ10: 9601.1917 | BR10: 9023.3666 | BS10: 9022.4383 | BT10: 9820.1075 | BU10: 10240.036 | BV10: 10264.881 | BW10: 10987.345 | BX10: 10715.001 | BY10: 11226.096 | BZ10: 11608.632 | CA10: 11665.626 | CB10: 11919.613 | CC10: 13078.19 | CD10: 12538.424 | CE10: 13349.292 | CF10: 12370.263 | CG10: 13060.155 | CH10: 13853.671 | CI10: 13091.204 | CJ10: 12710.473 | CK10: 13819.897 | CL10: 16554.107 | CM10: 16142.334 | CN10: 16466.41 | CO10: 17367.111
A11: Jujuy | B11: 438.01 | C11: 407.666 | D11: 389.469 | E11: 387.608 | F11: 401.33 | G11: 411.573 | H11: 398.074 | I11: 423.319 | J11: 480.4 | K11: 543.754 | L11: 526.702 | M11: 497.293 | N11: 541.608 | O11: 478.399 | P11: 476.106 | Q11: 397.196 | R11: 443.005 | S11: 488.585 | T11: 521.503 | U11: 552.236 | V11: 513.282 | W11: 604.01 | X11: 645.569 | Y11: 683.08438 | Z11: 821.655 | AA11: 820.617 | AB11: 869.66633 | AC11: 994.07 | AD11: 957.03733 | AE11: 1063.1877 | AF11: 1131.825 | AG11: 1215.8947 | AH11: 1257.9432 | AI11: 1332.0639 | AJ11: 1408.1584 | AK11: 1422.7615 | AL11: 1624.8662 | AM11: 1457.0884 | AN11: 1498.3919 | AO11: 1666.7488 | AP11: 1837.6928 | AQ11: 1827.1762 | AR11: 2116.9751 | AS11: 2284.1364 | AT11: 2398.0889 | AU11: 2488.3789 | AV11: 2656.237 | AW11: 2808.2302 | AX11: 3189.7777 | AY11: 3238.8701 | AZ11: 3531.212 | BA11: 3794.1666 | BB11: 4018.1921 | BC11: 4214.2651 | BD11: 4905.6083 | BE11: 5347.7119 | BF11: 5955.664 | BG11: 6715.7319 | BH11: 7500.1541 | BI11: 8338.2866 | BJ11: 10405.13 | BK11: 11120.939 | BL11: 11177.266 | BM11: 12479.586 | BN11: 12683.046 | BO11: 13340.631 | BP11: 13735.539 | BQ11: 15453.47 | BR11: 16117.727 | BS11: 16267.652 | BT11: 17755.676 | BU11: 17148.802 | BV11: 18620.765 | BW11: 19048.816 | BX11: 17933.676 | BY11: 18481.353 | BZ11: 20357.35 | CA11: 19949.355 | CB11: 21171.657 | CC11: 22537.394 | CD11: 22109.308 | CE11: 23794.703 | CF11: 22434.459 | CG11: 23710.1 | CH11: 25337.645 | CI11: 23522.391 | CJ11: 23692.42 | CK11: 24783.803 | CL11: 26407.681 | CM11: 26470.799 | CN11: 27597.065 | CO11: 27979.338
A12: La Pampa | B12: s.d | C12: s.d | D12: s.d | E12: s.d | F12: s.d | G12: s.d | H12: s.d | I12: s.d | J12: s.d | K12: s.d | L12: s.d | M12: s.d | N12: s.d | O12: s.d | P12: s.d | Q12: s.d | R12: s.d | S12: s.d | T12: s.d | U12: s.d | V12: s.d | W12: s.d | X12: s.d | Y12: s.d | Z12: s.d | AA12: s.d | AB12: s.d | AC12: s.d | AD12: s.d | AE12: s.d | AF12: s.d | AG12: s.d | AH12: s.d | AI12: s.d | AJ12: s.d | AK12: s.d | AL12: s.d | AM12: s.d | AN12: s.d | AO12: s.d | AP12: s.d | AQ12: s.d | AR12: s.d | AS12: s.d | AT12: s.d | AU12: s.d | AV12: s.d | AW12: s.d | AX12: s.d | AY12: s.d | AZ12: s.d | BA12: s.d | BB12: s.d | BC12: s.d | BD12: s.d | BE12: s.d | BF12: s.d | BG12: s.d | BH12: s.d | BI12: s.d | BJ12: 15340.836 | BK12: 15844.877 | BL12: 15690.135 | BM12: 17155.698 | BN12: 17099.708 | BO12: 19267.942 | BP12: 20998.209 | BQ12: 22191.683 | BR12: 22414.706 | BS12: 23468.925 | BT12: 23839.059 | BU12: 25187.907 | BV12: 26345.26 | BW12: 23981.625 | BX12: 23087.402 | BY12: 22587.139 | BZ12: 25031.75 | CA12: 29255.265 | CB12: 28885.152 | CC12: 32585.538 | CD12: 32271.155 | CE12: 32146.063 | CF12: 30298.762 | CG12: 38333.901 | CH12: 35892.893 | CI12: 25307.5 | CJ12: 34479.599 | CK12: 29660.028 | CL12: 32620.483 | CM12: 41994.21 | CN12: 39666.187
A13: La Rioja | B13: 183.99324 | C13: 157.39695 | D13: 155.0709 | E13: 178.15246 | F13: 168.31328 | G13: 179.1675 | H13: 184.73373 | I13: 213.47305 | J13: 233.09276 | K13: 207.48093 | L13: 239.64229 | M13: 223.00723 | N13: 255.28218 | O13: 211.63254 | P13: 198.98634 | Q13: 185.80531 | R13: 197.16821 | S13: 204.66527 | T13: 233.32263 | U13: 237.16121 | V13: 238.96468 | W13: 281.37853 | X13: 303.484 | Y13: 316.06695 | Z13: 419.90607 | AA13: 402.42025 | AB13: 424.23783 | AC13: 490.32 | AD13: 426.43466 | AE13: 481.06802 | AF13: 492.14744 | AG13: 517.23701 | AH13: 551.11384 | AI13: 573.60488 | AJ13: 610.74203 | AK13: 706.79567 | AL13: 737.42456 | AM13: 596.34806 | AN13: 669.05268 | AO13: 732.93394 | AP13: 794.86298 | AQ13: 867.86303 | AR13: 965.08542 | AS13: 1051.9722 | AT13: 1127.8132 | AU13: 1193.9681 | AV13: 1346.795 | AW13: 1504.8365 | AX13: 1393.1569 | AY13: 1180.3583 | AZ13: 1491.2778 | BA13: 1657.0315 | BB13: 1888.7083 | BC13: 1998.9471 | BD13: 2279.725 | BE13: 2443.7848 | BF13: 2659.8983 | BG13: 2861.337 | BH13: 3255.3197 | BI13: 3669.8562 | BJ13: 4476.1756 | BK13: 4950.0273 | BL13: 4877.9324 | BM13: 5959.8378 | BN13: 5991.1508 | BO13: 6432.2502 | BP13: 7370.6926 | BQ13: 7856.0561 | BR13: 7792.2182 | BS13: 8701.9305 | BT13: 10112.703 | BU13: 8901.7007 | BV13: 11304.258 | BW13: 8600.5973 | BX13: 9115.0688 | BY13: 9759.3357 | BZ13: 9549.2383 | CA13: 10325.337 | CB13: 10961.803 | CC13: 11502.077 | CD13: 11769.242 | CE13: 10888.693 | CF13: 10848.575 | CG13: 10925.139 | CH13: 11905.858 | CI13: 10431.229 | CJ13: 10141.297 | CK13: 12154.995 | CL13: 11506.151 | CM13: 12236.696 | CN13: 12720.151 | CO13: 11573.442
A14: Mendoza | B14: 2195.5297 | C14: 2103.3637 | D14: 2143.7913 | E14: 2277.2868 | F14: 2456.0531 | G14: 2334.066 | H14: 2419.7551 | I14: 2761.1718 | J14: 2874.2497 | K14: 2863.7178 | L14: 2963.8175 | M14: 2857.0675 | N14: 3068.4769 | O14: 3246.5831 | P14: 2869.9348 | Q14: 2711.7221 | R14: 2558.7962 | S14: 2601.4994 | T14: 2800.0376 | U14: 3271.9008 | V14: 3102.3453 | W14: 3254.2088 | X14: 3590.3817 | Y14: 3619.1406 | Z14: 4210.3332 | AA14: 4035.9201 | AB14: 3969.1979 | AC14: 4446.8 | AD14: 4285.9185 | AE14: 4477.2595 | AF14: 4653.1124 | AG14: 4977.7822 | AH14: 5349.0907 | AI14: 5368.8962 | AJ14: 5800.0187 | AK14: 6548.1781 | AL14: 6815.2756 | AM14: 6525.0879 | AN14: 6633.6134 | AO14: 7882.9436 | AP14: 8485.1487 | AQ14: 8272.2309 | AR14: 9777.1449 | AS14: 10673.847 | AT14: 10903.034 | AU14: 11468.664 | AV14: 12420.676 | AW14: 12973.07 | AX14: 14525.561 | AY14: 14960.067 | AZ14: 15059.685 | BA14: 17487.4 | BB14: 18906.731 | BC14: 20011.321 | BD14: 22575.36 | BE14: 24771.434 | BF14: 28058.794 | BG14: 33556.861 | BH14: 35453.717 | BI14: 36875.547 | BJ14: 47346.037 | BK14: 52411.426 | BL14: 56751.087 | BM14: 60502.131 | BN14: 64921.411 | BO14: 66006.863 | BP14: 66390.438 | BQ14: 72004.543 | BR14: 74241.057 | BS14: 79689.758 | BT14: 79511.978 | BU14: 79191.108 | BV14: 83128.051 | BW14: 79687.228 | BX14: 77140.914 | BY14: 81188.032 | BZ14: 90317.924 | CA14: 90551.713 | CB14: 93159.789 | CC14: 100530.8 | CD14: 99069.176 | CE14: 103667.38 | CF14: 106688.39 | CG14: 102452.58 | CH14: 117078.45 | CI14: 107684.3 | CJ14: 102299.49 | CK14: 110785.14 | CL14: 117822.89 | CM14: 116053.38 | CN14: 117457.98 | CO14: 121430.41
